Workbook

Sheet All departments
A1: NISMCAA 10th Edition (Nigeria Grand Finale) - Action plan: all departments
A2: PROPOSED: Nov 11, 2027 (Thursday). Subject to sponsor approval; may still change. (John, Oct 26, 2026) Everything is planned to finish EARLY: all work done by Sep 30, 2027, hard limit Oct 14, 2027 (4 weeks before).
B4: Event date (PROPOSED; change here if sponsors move it) | C4: 46702 | D4: All event-linked dates after Mar 31, 2027 follow this cell. | H4: =IF(G23+H23=0,"BEHIND SCHEDULE: NONE"&CHAR(10)&"Nothing has started yet, so nothing is late. "&D23&" tasks, all Not started.","BEHIND SCHEDULE: "&(G23+H23)&" TASK(S)"&CHAR(10)&G23&" red, "&H23&" amber. See the table below and each department sheet.") -> BEHIND SCHEDULE: NONE Nothing has started yet, so nothing is late. 222 tasks, all Not started.
B5: Today | C5: =TODAY() -> 46321
B6: Days to the event | C6: =C4-C5 -> 381
B7: Planned: ALL work done (6 weeks before) | C7: =C4-42 -> 46660 | D7: Every build task has a planned finish on or before this day.
B8: Hard limit: all work finished (4 weeks before) | C8: =C4-28 -> 46674 | D8: Planned finish + 2 weeks at the latest. After this: no new tasks.
B9: Review / rehearsal / contingency window starts | C9: =C4-27 -> 46675 | D9: Runs to the day before the event. Review only.
A11: DEPARTMENTS
A12: # | B12: Department | C12: Lead | D12: Tasks | E12: Done | F12: Avg % progress | G12: RED | H12: AMBER | I12: GREEN | J12: GREY | K12: Status | L12: Last planned finish (before the final 4 weeks) | M12: Next open deadline | N12: Behind: task numbers
A13: 1 | B13: Office of the Founder | C13: John (Founder) | D13: =COUNT('Office of the Founder'!A6:A26) -> 16 | E13: =COUNTIF('Office of the Founder'!G6:G26,"Done") -> 0 | F13: =IFERROR(AVERAGE('Office of the Founder'!H6:H26),0) -> 0 | G13: =COUNTIF('Office of the Founder'!L6:L26,"RED") -> 0 | H13: =COUNTIF('Office of the Founder'!L6:L26,"AMBER") -> 0 | I13: =COUNTIF('Office of the Founder'!L6:L26,"GREEN") -> 16 | J13: =COUNTIF('Office of the Founder'!L6:L26,"GREY") -> 0 | K13: =IF(G13>0,"BEHIND",IF(H13>0,"AT RISK","On track")) -> On track | L13: =_xlfn.MAXIFS('Office of the Founder'!E6:E26,'Office of the Founder'!E6:E26,"<="&(EventDate-28)) -> 46660 | M13: =IFERROR(_xlfn.MINIFS('Office of the Founder'!E6:E26,'Office of the Founder'!G6:G26,"<>Done",'Office of the Founder'!E6:E26,">="&TODAY()),"-") -> 46332 | N13: {=IF(G13+H13=0,"-",_xlfn.TEXTJOIN(", ",TRUE(),IF(('Office of the Founder'!L6:L26="RED")+('Office of the Founder'!L6:L26="AMBER"),"#"&'Office of the Founder'!A6:A26,"")))} -> -
A14: 2 | B14: Programs & Competition | C14: Project Manager | D14: =COUNT('Programs & Competition'!A6:A37) -> 27 | E14: =COUNTIF('Programs & Competition'!G6:G37,"Done") -> 0 | F14: =IFERROR(AVERAGE('Programs & Competition'!H6:H37),0) -> 0 | G14: =COUNTIF('Programs & Competition'!L6:L37,"RED") -> 0 | H14: =COUNTIF('Programs & Competition'!L6:L37,"AMBER") -> 0 | I14: =COUNTIF('Programs & Competition'!L6:L37,"GREEN") -> 27 | J14: =COUNTIF('Programs & Competition'!L6:L37,"GREY") -> 0 | K14: =IF(G14>0,"BEHIND",IF(H14>0,"AT RISK","On track")) -> On track | L14: =_xlfn.MAXIFS('Programs & Competition'!E6:E37,'Programs & Competition'!E6:E37,"<="&(EventDate-28)) -> 46660 | M14: =IFERROR(_xlfn.MINIFS('Programs & Competition'!E6:E37,'Programs & Competition'!G6:G37,"<>Done",'Programs & Competition'!E6:E37,">="&TODAY()),"-") -> 46360 | N14: {=IF(G14+H14=0,"-",_xlfn.TEXTJOIN(", ",TRUE(),IF(('Programs & Competition'!L6:L37="RED")+('Programs & Competition'!L6:L37="AMBER"),"#"&'Programs & Competition'!A6:A37,"")))} -> -
A15: 3 | B15: Child Welfare & Safeguarding | C15: To be appointed | D15: =COUNT('Child Welfare & Safeguarding'!A6:A30) -> 20 | E15: =COUNTIF('Child Welfare & Safeguarding'!G6:G30,"Done") -> 0 | F15: =IFERROR(AVERAGE('Child Welfare & Safeguarding'!H6:H30),0) -> 0 | G15: =COUNTIF('Child Welfare & Safeguarding'!L6:L30,"RED") -> 0 | H15: =COUNTIF('Child Welfare & Safeguarding'!L6:L30,"AMBER") -> 0 | I15: =COUNTIF('Child Welfare & Safeguarding'!L6:L30,"GREEN") -> 20 | J15: =COUNTIF('Child Welfare & Safeguarding'!L6:L30,"GREY") -> 0 | K15: =IF(G15>0,"BEHIND",IF(H15>0,"AT RISK","On track")) -> On track | L15: =_xlfn.MAXIFS('Child Welfare & Safeguarding'!E6:E30,'Child Welfare & Safeguarding'!E6:E30,"<="&(EventDate-28)) -> 46660 | M15: =IFERROR(_xlfn.MINIFS('Child Welfare & Safeguarding'!E6:E30,'Child Welfare & Safeguarding'!G6:G30,"<>Done",'Child Welfare & Safeguarding'!E6:E30,">="&TODAY()),"-") -> 46346 | N15: {=IF(G15+H15=0,"-",_xlfn.TEXTJOIN(", ",TRUE(),IF(('Child Welfare & Safeguarding'!L6:L30="RED")+('Child Welfare & Safeguarding'!L6:L30="AMBER"),"#"&'Child Welfare & Safeguarding'!A6:A30,"")))} -> -
A16: 4 | B16: Event Operations | C16: To be appointed | D16: =COUNT('Event Operations'!A6:A35) -> 25 | E16: =COUNTIF('Event Operations'!G6:G35,"Done") -> 0 | F16: =IFERROR(AVERAGE('Event Operations'!H6:H35),0) -> 0 | G16: =COUNTIF('Event Operations'!L6:L35,"RED") -> 0 | H16: =COUNTIF('Event Operations'!L6:L35,"AMBER") -> 0 | I16: =COUNTIF('Event Operations'!L6:L35,"GREEN") -> 25 | J16: =COUNTIF('Event Operations'!L6:L35,"GREY") -> 0 | K16: =IF(G16>0,"BEHIND",IF(H16>0,"AT RISK","On track")) -> On track | L16: =_xlfn.MAXIFS('Event Operations'!E6:E35,'Event Operations'!E6:E35,"<="&(EventDate-28)) -> 46660 | M16: =IFERROR(_xlfn.MINIFS('Event Operations'!E6:E35,'Event Operations'!G6:G35,"<>Done",'Event Operations'!E6:E35,">="&TODAY()),"-") -> 46374 | N16: {=IF(G16+H16=0,"-",_xlfn.TEXTJOIN(", ",TRUE(),IF(('Event Operations'!L6:L35="RED")+('Event Operations'!L6:L35="AMBER"),"#"&'Event Operations'!A6:A35,"")))} -> -
A17: 5 | B17: Media & Communications | C17: To be appointed | D17: =COUNT('Media & Communications'!A6:A37) -> 27 | E17: =COUNTIF('Media & Communications'!G6:G37,"Done") -> 0 | F17: =IFERROR(AVERAGE('Media & Communications'!H6:H37),0) -> 0 | G17: =COUNTIF('Media & Communications'!L6:L37,"RED") -> 0 | H17: =COUNTIF('Media & Communications'!L6:L37,"AMBER") -> 0 | I17: =COUNTIF('Media & Communications'!L6:L37,"GREEN") -> 27 | J17: =COUNTIF('Media & Communications'!L6:L37,"GREY") -> 0 | K17: =IF(G17>0,"BEHIND",IF(H17>0,"AT RISK","On track")) -> On track | L17: =_xlfn.MAXIFS('Media & Communications'!E6:E37,'Media & Communications'!E6:E37,"<="&(EventDate-28)) -> 46660 | M17: =IFERROR(_xlfn.MINIFS('Media & Communications'!E6:E37,'Media & Communications'!G6:G37,"<>Done",'Media & Communications'!E6:E37,">="&TODAY()),"-") -> 46332 | N17: {=IF(G17+H17=0,"-",_xlfn.TEXTJOIN(", ",TRUE(),IF(('Media & Communications'!L6:L37="RED")+('Media & Communications'!L6:L37="AMBER"),"#"&'Media & Communications'!A6:A37,"")))} -> -
A18: 6 | B18: Partnerships & Sponsorship | C18: To be appointed | D18: =COUNT('Partnerships & Sponsorship'!A6:A38) -> 28 | E18: =COUNTIF('Partnerships & Sponsorship'!G6:G38,"Done") -> 0 | F18: =IFERROR(AVERAGE('Partnerships & Sponsorship'!H6:H38),0) -> 0 | G18: =COUNTIF('Partnerships & Sponsorship'!L6:L38,"RED") -> 0 | H18: =COUNTIF('Partnerships & Sponsorship'!L6:L38,"AMBER") -> 0 | I18: =COUNTIF('Partnerships & Sponsorship'!L6:L38,"GREEN") -> 28 | J18: =COUNTIF('Partnerships & Sponsorship'!L6:L38,"GREY") -> 0 | K18: =IF(G18>0,"BEHIND",IF(H18>0,"AT RISK","On track")) -> On track | L18: =_xlfn.MAXIFS('Partnerships & Sponsorship'!E6:E38,'Partnerships & Sponsorship'!E6:E38,"<="&(EventDate-28)) -> 46660 | M18: =IFERROR(_xlfn.MINIFS('Partnerships & Sponsorship'!E6:E38,'Partnerships & Sponsorship'!G6:G38,"<>Done",'Partnerships & Sponsorship'!E6:E38,">="&TODAY()),"-") -> 46324 | N18: {=IF(G18+H18=0,"-",_xlfn.TEXTJOIN(", ",TRUE(),IF(('Partnerships & Sponsorship'!L6:L38="RED")+('Partnerships & Sponsorship'!L6:L38="AMBER"),"#"&'Partnerships & Sponsorship'!A6:A38,"")))} -> -
A19: 7 | B19: Academy & Education | C19: To be appointed | D19: =COUNT('Academy & Education'!A6:A27) -> 17 | E19: =COUNTIF('Academy & Education'!G6:G27,"Done") -> 0 | F19: =IFERROR(AVERAGE('Academy & Education'!H6:H27),0) -> 0 | G19: =COUNTIF('Academy & Education'!L6:L27,"RED") -> 0 | H19: =COUNTIF('Academy & Education'!L6:L27,"AMBER") -> 0 | I19: =COUNTIF('Academy & Education'!L6:L27,"GREEN") -> 17 | J19: =COUNTIF('Academy & Education'!L6:L27,"GREY") -> 0 | K19: =IF(G19>0,"BEHIND",IF(H19>0,"AT RISK","On track")) -> On track | L19: =_xlfn.MAXIFS('Academy & Education'!E6:E27,'Academy & Education'!E6:E27,"<="&(EventDate-28)) -> 46660 | M19: =IFERROR(_xlfn.MINIFS('Academy & Education'!E6:E27,'Academy & Education'!G6:G27,"<>Done",'Academy & Education'!E6:E27,">="&TODAY()),"-") -> 46367 | N19: {=IF(G19+H19=0,"-",_xlfn.TEXTJOIN(", ",TRUE(),IF(('Academy & Education'!L6:L27="RED")+('Academy & Education'!L6:L27="AMBER"),"#"&'Academy & Education'!A6:A27,"")))} -> -
A20: 8 | B20: Finance & Admin | C20: Executive Director | D20: =COUNT('Finance & Admin'!A6:A31) -> 21 | E20: =COUNTIF('Finance & Admin'!G6:G31,"Done") -> 0 | F20: =IFERROR(AVERAGE('Finance & Admin'!H6:H31),0) -> 0 | G20: =COUNTIF('Finance & Admin'!L6:L31,"RED") -> 0 | H20: =COUNTIF('Finance & Admin'!L6:L31,"AMBER") -> 0 | I20: =COUNTIF('Finance & Admin'!L6:L31,"GREEN") -> 21 | J20: =COUNTIF('Finance & Admin'!L6:L31,"GREY") -> 0 | K20: =IF(G20>0,"BEHIND",IF(H20>0,"AT RISK","On track")) -> On track | L20: =_xlfn.MAXIFS('Finance & Admin'!E6:E31,'Finance & Admin'!E6:E31,"<="&(EventDate-28)) -> 46660 | M20: =IFERROR(_xlfn.MINIFS('Finance & Admin'!E6:E31,'Finance & Admin'!G6:G31,"<>Done",'Finance & Admin'!E6:E31,">="&TODAY()),"-") -> 46353 | N20: {=IF(G20+H20=0,"-",_xlfn.TEXTJOIN(", ",TRUE(),IF(('Finance & Admin'!L6:L31="RED")+('Finance & Admin'!L6:L31="AMBER"),"#"&'Finance & Admin'!A6:A31,"")))} -> -
A21: 9 | B21: Technology | C21: To be appointed | D21: =COUNT(Technology!A6:A34) -> 24 | E21: =COUNTIF(Technology!G6:G34,"Done") -> 0 | F21: =IFERROR(AVERAGE(Technology!H6:H34),0) -> 0 | G21: =COUNTIF(Technology!L6:L34,"RED") -> 0 | H21: =COUNTIF(Technology!L6:L34,"AMBER") -> 0 | I21: =COUNTIF(Technology!L6:L34,"GREEN") -> 24 | J21: =COUNTIF(Technology!L6:L34,"GREY") -> 0 | K21: =IF(G21>0,"BEHIND",IF(H21>0,"AT RISK","On track")) -> On track | L21: =_xlfn.MAXIFS(Technology!E6:E34,Technology!E6:E34,"<="&(EventDate-28)) -> 46660 | M21: =IFERROR(_xlfn.MINIFS(Technology!E6:E34,Technology!G6:G34,"<>Done",Technology!E6:E34,">="&TODAY()),"-") -> 46339 | N21: {=IF(G21+H21=0,"-",_xlfn.TEXTJOIN(", ",TRUE(),IF((Technology!L6:L34="RED")+(Technology!L6:L34="AMBER"),"#"&Technology!A6:A34,"")))} -> -
A22: 10 | B22: International & Diplomacy | C22: Abisade (Legal & Diplomacy Director) | D22: =COUNT('International & Diplomacy'!A6:A27) -> 17 | E22: =COUNTIF('International & Diplomacy'!G6:G27,"Done") -> 0 | F22: =IFERROR(AVERAGE('International & Diplomacy'!H6:H27),0) -> 0 | G22: =COUNTIF('International & Diplomacy'!L6:L27,"RED") -> 0 | H22: =COUNTIF('International & Diplomacy'!L6:L27,"AMBER") -> 0 | I22: =COUNTIF('International & Diplomacy'!L6:L27,"GREEN") -> 17 | J22: =COUNTIF('International & Diplomacy'!L6:L27,"GREY") -> 0 | K22: =IF(G22>0,"BEHIND",IF(H22>0,"AT RISK","On track")) -> On track | L22: =_xlfn.MAXIFS('International & Diplomacy'!E6:E27,'International & Diplomacy'!E6:E27,"<="&(EventDate-28)) -> 46660 | M22: =IFERROR(_xlfn.MINIFS('International & Diplomacy'!E6:E27,'International & Diplomacy'!G6:G27,"<>Done",'International & Diplomacy'!E6:E27,">="&TODAY()),"-") -> 46346 | N22: {=IF(G22+H22=0,"-",_xlfn.TEXTJOIN(", ",TRUE(),IF(('International & Diplomacy'!L6:L27="RED")+('International & Diplomacy'!L6:L27="AMBER"),"#"&'International & Diplomacy'!A6:A27,"")))} -> -
B23: ALL DEPARTMENTS | D23: =SUM(D13:D22) -> 222 | E23: =SUM(E13:E22) -> 0 | F23: =IFERROR(SUMPRODUCT(D13:D22,F13:F22)/D23,0) -> 0 | G23: =SUM(G13:G22) -> 0 | H23: =SUM(H13:H22) -> 0 | I23: =SUM(I13:I22) -> 222 | J23: =SUM(J13:J22) -> 0 | K23: =IF(G23>0,"BEHIND",IF(H23>0,"AT RISK","On track")) -> On track | L23: =MAX(L13:L22) -> 46660
A25: KEY MILESTONES (new plan around Nov 11, 2027)
A26: # | B26: Milestone | D26: Planned date | E26: Days from today | F26: Weeks before the event | G26: Why / what moved (full list on 'Milestone shifts')
A27: 1 | B27: Plan approved; legal status and budget work started | D27: 46374 | E27: =D27-TODAY() -> 53 | F27: =ROUND((EventDate-D27)/7,1) -> 46.9 | G27: Start unchanged (now). Each item now has a finish date: gap list Nov 6, handles Nov 13, venue shortlist Dec 18, 2026.
A28: 2 | B28: Sponsor packs sent to the top 15 leads | D28: 46374 | E28: =D28-TODAY() -> 53 | F28: =ROUND((EventDate-D28)/7,1) -> 46.9 | G28: About 6 weeks later than the old draft, because the funding plan builds the deck first (days 15-45, to Nov 27). The event is 8 months later, so there is no pressure to send earlier than a good deck.
A29: 3 | B29: Venue booked in writing | D29: =EventDate-195 -> 46507 | E29: =D29-TODAY() -> 186 | F29: =ROUND((EventDate-D29)/7,1) -> 27.9 | G29: Booked 6.5 months before the event instead of 4. A provisional hold is placed by Mar 12, 2027. The written booking waits for the Mar 31 sponsor-approval gate. Shortlist and quotes come first.
A30: 4 | B30: Lagos Ministry endorsement approached | D30: 46416 | E30: =D30-TODAY() -> 95 | F30: =ROUND((EventDate-D30)/7,1) -> 40.9 | G30: Moved to Dec 2026-Jan 2027 so the sponsor pack and a venue shortlist go with the request.
A31: 5 | B31: Theme chosen; 10th Edition announced; registration open | D31: 46398 | E31: =D31-TODAY() -> 77 | F31: =ROUND((EventDate-D31)/7,1) -> 43.4 | G31: Theme by Dec 11, 2026. Announcement Jan 11, 2027 (10 months before the event) so the date wording is settled first. Registration stays open from Nov 16, 2026 per the old plan.
A32: 6 | B32: Rulebook frozen; judges and auditor recruited; scoring tool chosen | D32: 46374 | E32: =D32-TODAY() -> 53 | F32: =ROUND((EventDate-D32)/7,1) -> 46.9 | G32: Rulebook frozen Dec 18, 2026 (Jury plan). Judge recruitment opens Jan 2027, the course runs Apr-May, certificates Jun 18, auditor by Apr 30, 2027, as in the Jury plan. Press briefing Jan 22.
A33: 7 | B33: Sponsor contracts and online campaign | D33: =EventDate-72 -> 46630 | E33: =D33-TODAY() -> 309 | F33: =ROUND((EventDate-D33)/7,1) -> 10.3 | G33: Follow-ups Jan 12; headline and gold sponsors in writing by Jun 30; every agreement by Aug 31, 2027. Online-only activity around Jan 16 and Feb 6, 2027 is kept.
A34: 8 | B34: Sponsor-approval gate: date confirmed or changed | D34: 46477 | E34: =D34-TODAY() -> 156 | F34: =ROUND((EventDate-D34)/7,1) -> 32.1 | G34: New gate, because the date is proposed and subject to sponsor approval. If the date moves, change one cell and every later date moves with it.
A35: 9 | B35: Registration and Academic Award nominations close | D35: =EventDate-134 -> 46568 | E35: =D35-TODAY() -> 247 | F35: =ROUND((EventDate-D35)/7,1) -> 19.1 | G35: Closes 4.5 months before the event (old plan: 6 weeks before). Qualifying rounds then have July and August.
A36: 10 | B36: Qualifying rounds and scoring dry run | D36: =EventDate-76 -> 46626 | E36: =D36-TODAY() -> 305 | F36: =ROUND((EventDate-D36)/7,1) -> 10.9 | G36: Dry run is the mock round (Jun 25). Qualifying rounds Jul 5-Aug 27, 2027, as the Jury plan says Jul-Sep, pulled to finish early.
A37: 11 | B37: Finalists announced; technical rehearsal plan and run sheet; media accreditation | D37: =EventDate-48 -> 46654 | E37: =D37-TODAY() -> 333 | F37: =ROUND((EventDate-D37)/7,1) -> 6.9 | G37: Finalists Sep 10, 2027. Rehearsal plan and run sheet Sep 24. Accreditation closes Sep 30.
A38: 12 | B38: Program printing, judge briefing, mock scoring audit | D38: =EventDate-42 -> 46660 | E38: =D38-TODAY() -> 339 | F38: =ROUND((EventDate-D38)/7,1) -> 6 | G38: These were in the last 12 days. They now finish by Sep 30, 2027 (printing, mock audit and rehearsal #1). The judges' final briefing and rehearsal #2 are in the review window, as review only.
A39: 13 | B39: ALL WORK DONE (planned) | D39: =EventDate-42 -> 46660 | E39: =D39-TODAY() -> 339 | F39: =ROUND((EventDate-D39)/7,1) -> 6 | G39: John's rule. Every build task finishes by Sep 30, 2027. The hard limit for every task is Oct 14, 2027 (4 weeks before the event).
A40: 14 | B40: Hard limit: all work finished | D40: =EventDate-28 -> 46674 | E40: =D40-TODAY() -> 353 | F40: =ROUND((EventDate-D40)/7,1) -> 4 | G40: Event date minus 28 days. After this: no new tasks.
A41: 15 | B41: Review, rehearsal and contingency window | D41: =EventDate-27 -> 46675 | E41: =D41-TODAY() -> 354 | F41: =ROUND((EventDate-D41)/7,1) -> 3.9 | G41: Oct 15 to Nov 10, 2027: review, rehearsal and contingency only.
A42: 16 | B42: 10th Edition Grand Finale (PROPOSED) | D42: =EventDate -> 46702 | E42: =D42-TODAY() -> 381 | F42: =ROUND((EventDate-D42)/7,1) -> 0 | G42: Replaced by Nov 11, 2027 (John, Oct 26, 2026), a Thursday. Subject to sponsor approval; may still change. The old reasons (elections, Ramadan) no longer apply to this date; the school calendar check is a task in Event Operations.
A43: 17 | B43: Results and score summary published; sponsor reports | D43: =EventDate+7 -> 46709 | E43: =D43-TODAY() -> 388 | F43: =ROUND((EventDate-D43)/7,1) -> -1 | G43: Same rule: 7 days after the event.
...

Sheet Timeline
A1: Timeline: how many tasks are active in each department, by month (Oct 2026 - Dec 2027)
A2: PROPOSED: Nov 11, 2027 (Thursday). Subject to sponsor approval; may still change. (John, Oct 26, 2026)
A4: Department | B4: Lead | C4: 46296 | D4: 46327 | E4: 46357 | F4: 46388 | G4: 46419 | H4: 46447 | I4: 46478 | J4: 46508 | K4: 46539 | L4: 46569 | M4: 46600 | N4: 46631 | O4: 46661 | P4: 46692 | Q4: 46722
A5: Office of the Founder | B5: John (Founder) | C5: =COUNTIFS('Office of the Founder'!$D$6:$D$26,"<="&EOMONTH(C$4,0),'Office of the Founder'!$E$6:$E$26,">="&C$4) -> 3 | D5: =COUNTIFS('Office of the Founder'!$D$6:$D$26,"<="&EOMONTH(D$4,0),'Office of the Founder'!$E$6:$E$26,">="&D$4) -> 6 | E5: =COUNTIFS('Office of the Founder'!$D$6:$D$26,"<="&EOMONTH(E$4,0),'Office of the Founder'!$E$6:$E$26,">="&E$4) -> 4 | F5: =COUNTIFS('Office of the Founder'!$D$6:$D$26,"<="&EOMONTH(F$4,0),'Office of the Founder'!$E$6:$E$26,">="&F$4) -> 4 | G5: =COUNTIFS('Office of the Founder'!$D$6:$D$26,"<="&EOMONTH(G$4,0),'Office of the Founder'!$E$6:$E$26,">="&G$4) -> 3 | H5: =COUNTIFS('Office of the Founder'!$D$6:$D$26,"<="&EOMONTH(H$4,0),'Office of the Founder'!$E$6:$E$26,">="&H$4) -> 3 | I5: =COUNTIFS('Office of the Founder'!$D$6:$D$26,"<="&EOMONTH(I$4,0),'Office of the Founder'!$E$6:$E$26,">="&I$4) -> 2 | J5: =COUNTIFS('Office of the Founder'!$D$6:$D$26,"<="&EOMONTH(J$4,0),'Office of the Founder'!$E$6:$E$26,">="&J$4) -> 2 | ... Q5: =COUNTIFS('Office of the Founder'!$D$6:$D$26,"<="&EOMONTH(Q$4,0),'Office of the Founder'!$E$6:$E$26,">="&Q$4) -> 1
A6: Programs & Competition | B6: Project Manager | C6: =COUNTIFS('Programs & Competition'!$D$6:$D$37,"<="&EOMONTH(C$4,0),'Programs & Competition'!$E$6:$E$37,">="&C$4) -> 0 | D6: =COUNTIFS('Programs & Competition'!$D$6:$D$37,"<="&EOMONTH(D$4,0),'Programs & Competition'!$E$6:$E$37,">="&D$4) -> 2 | E6: =COUNTIFS('Programs & Competition'!$D$6:$D$37,"<="&EOMONTH(E$4,0),'Programs & Competition'!$E$6:$E$37,">="&E$4) -> 3 | F6: =COUNTIFS('Programs & Competition'!$D$6:$D$37,"<="&EOMONTH(F$4,0),'Programs & Competition'!$E$6:$E$37,">="&F$4) -> 3 | G6: =COUNTIFS('Programs & Competition'!$D$6:$D$37,"<="&EOMONTH(G$4,0),'Programs & Competition'!$E$6:$E$37,">="&G$4) -> 4 | H6: =COUNTIFS('Programs & Competition'!$D$6:$D$37,"<="&EOMONTH(H$4,0),'Programs & Competition'!$E$6:$E$37,">="&H$4) -> 4 | I6: =COUNTIFS('Programs & Competition'!$D$6:$D$37,"<="&EOMONTH(I$4,0),'Programs & Competition'!$E$6:$E$37,">="&I$4) -> 2 | J6: =COUNTIFS('Programs & Competition'!$D$6:$D$37,"<="&EOMONTH(J$4,0),'Programs & Competition'!$E$6:$E$37,">="&J$4) -> 2 | ... Q6: =COUNTIFS('Programs & Competition'!$D$6:$D$37,"<="&EOMONTH(Q$4,0),'Programs & Competition'!$E$6:$E$37,">="&Q$4) -> 1
A7: Child Welfare & Safeguarding | B7: To be appointed | C7: =COUNTIFS('Child Welfare & Safeguarding'!$D$6:$D$30,"<="&EOMONTH(C$4,0),'Child Welfare & Safeguarding'!$E$6:$E$30,">="&C$4) -> 1 | D7: =COUNTIFS('Child Welfare & Safeguarding'!$D$6:$D$30,"<="&EOMONTH(D$4,0),'Child Welfare & Safeguarding'!$E$6:$E$30,">="&D$4) -> 3 | E7: =COUNTIFS('Child Welfare & Safeguarding'!$D$6:$D$30,"<="&EOMONTH(E$4,0),'Child Welfare & Safeguarding'!$E$6:$E$30,">="&E$4) -> 3 | F7: =COUNTIFS('Child Welfare & Safeguarding'!$D$6:$D$30,"<="&EOMONTH(F$4,0),'Child Welfare & Safeguarding'!$E$6:$E$30,">="&F$4) -> 2 | G7: =COUNTIFS('Child Welfare & Safeguarding'!$D$6:$D$30,"<="&EOMONTH(G$4,0),'Child Welfare & Safeguarding'!$E$6:$E$30,">="&G$4) -> 1 | H7: =COUNTIFS('Child Welfare & Safeguarding'!$D$6:$D$30,"<="&EOMONTH(H$4,0),'Child Welfare & Safeguarding'!$E$6:$E$30,">="&H$4) -> 2 | I7: =COUNTIFS('Child Welfare & Safeguarding'!$D$6:$D$30,"<="&EOMONTH(I$4,0),'Child Welfare & Safeguarding'!$E$6:$E$30,">="&I$4) -> 2 | J7: =COUNTIFS('Child Welfare & Safeguarding'!$D$6:$D$30,"<="&EOMONTH(J$4,0),'Child Welfare & Safeguarding'!$E$6:$E$30,">="&J$4) -> 3 | ... Q7: =COUNTIFS('Child Welfare & Safeguarding'!$D$6:$D$30,"<="&EOMONTH(Q$4,0),'Child Welfare & Safeguarding'!$E$6:$E$30,">="&Q$4) -> 1
A8: Event Operations | B8: To be appointed | C8: =COUNTIFS('Event Operations'!$D$6:$D$35,"<="&EOMONTH(C$4,0),'Event Operations'!$E$6:$E$35,">="&C$4) -> 0 | D8: =COUNTIFS('Event Operations'!$D$6:$D$35,"<="&EOMONTH(D$4,0),'Event Operations'!$E$6:$E$35,">="&D$4) -> 1 | E8: =COUNTIFS('Event Operations'!$D$6:$D$35,"<="&EOMONTH(E$4,0),'Event Operations'!$E$6:$E$35,">="&E$4) -> 2 | F8: =COUNTIFS('Event Operations'!$D$6:$D$35,"<="&EOMONTH(F$4,0),'Event Operations'!$E$6:$E$35,">="&F$4) -> 2 | G8: =COUNTIFS('Event Operations'!$D$6:$D$35,"<="&EOMONTH(G$4,0),'Event Operations'!$E$6:$E$35,">="&G$4) -> 2 | H8: =COUNTIFS('Event Operations'!$D$6:$D$35,"<="&EOMONTH(H$4,0),'Event Operations'!$E$6:$E$35,">="&H$4) -> 1 | I8: =COUNTIFS('Event Operations'!$D$6:$D$35,"<="&EOMONTH(I$4,0),'Event Operations'!$E$6:$E$35,">="&I$4) -> 2 | J8: =COUNTIFS('Event Operations'!$D$6:$D$35,"<="&EOMONTH(J$4,0),'Event Operations'!$E$6:$E$35,">="&J$4) -> 4 | ... Q8: =COUNTIFS('Event Operations'!$D$6:$D$35,"<="&EOMONTH(Q$4,0),'Event Operations'!$E$6:$E$35,">="&Q$4) -> 1
A9: Media & Communications | B9: To be appointed | C9: =COUNTIFS('Media & Communications'!$D$6:$D$37,"<="&EOMONTH(C$4,0),'Media & Communications'!$E$6:$E$37,">="&C$4) -> 2 | D9: =COUNTIFS('Media & Communications'!$D$6:$D$37,"<="&EOMONTH(D$4,0),'Media & Communications'!$E$6:$E$37,">="&D$4) -> 7 | E9: =COUNTIFS('Media & Communications'!$D$6:$D$37,"<="&EOMONTH(E$4,0),'Media & Communications'!$E$6:$E$37,">="&E$4) -> 6 | F9: =COUNTIFS('Media & Communications'!$D$6:$D$37,"<="&EOMONTH(F$4,0),'Media & Communications'!$E$6:$E$37,">="&F$4) -> 5 | G9: =COUNTIFS('Media & Communications'!$D$6:$D$37,"<="&EOMONTH(G$4,0),'Media & Communications'!$E$6:$E$37,">="&G$4) -> 6 | H9: =COUNTIFS('Media & Communications'!$D$6:$D$37,"<="&EOMONTH(H$4,0),'Media & Communications'!$E$6:$E$37,">="&H$4) -> 4 | I9: =COUNTIFS('Media & Communications'!$D$6:$D$37,"<="&EOMONTH(I$4,0),'Media & Communications'!$E$6:$E$37,">="&I$4) -> 3 | J9: =COUNTIFS('Media & Communications'!$D$6:$D$37,"<="&EOMONTH(J$4,0),'Media & Communications'!$E$6:$E$37,">="&J$4) -> 4 | ... Q9: =COUNTIFS('Media & Communications'!$D$6:$D$37,"<="&EOMONTH(Q$4,0),'Media & Communications'!$E$6:$E$37,">="&Q$4) -> 1
A10: Partnerships & Sponsorship | B10: To be appointed | C10: =COUNTIFS('Partnerships & Sponsorship'!$D$6:$D$38,"<="&EOMONTH(C$4,0),'Partnerships & Sponsorship'!$E$6:$E$38,">="&C$4) -> 3 | D10: =COUNTIFS('Partnerships & Sponsorship'!$D$6:$D$38,"<="&EOMONTH(D$4,0),'Partnerships & Sponsorship'!$E$6:$E$38,">="&D$4) -> 6 | E10: =COUNTIFS('Partnerships & Sponsorship'!$D$6:$D$38,"<="&EOMONTH(E$4,0),'Partnerships & Sponsorship'!$E$6:$E$38,">="&E$4) -> 7 | F10: =COUNTIFS('Partnerships & Sponsorship'!$D$6:$D$38,"<="&EOMONTH(F$4,0),'Partnerships & Sponsorship'!$E$6:$E$38,">="&F$4) -> 7 | G10: =COUNTIFS('Partnerships & Sponsorship'!$D$6:$D$38,"<="&EOMONTH(G$4,0),'Partnerships & Sponsorship'!$E$6:$E$38,">="&G$4) -> 5 | H10: =COUNTIFS('Partnerships & Sponsorship'!$D$6:$D$38,"<="&EOMONTH(H$4,0),'Partnerships & Sponsorship'!$E$6:$E$38,">="&H$4) -> 6 | I10: =COUNTIFS('Partnerships & Sponsorship'!$D$6:$D$38,"<="&EOMONTH(I$4,0),'Partnerships & Sponsorship'!$E$6:$E$38,">="&I$4) -> 5 | J10: =COUNTIFS('Partnerships & Sponsorship'!$D$6:$D$38,"<="&EOMONTH(J$4,0),'Partnerships & Sponsorship'!$E$6:$E$38,">="&J$4) -> 5 | ... Q10: =COUNTIFS('Partnerships & Sponsorship'!$D$6:$D$38,"<="&EOMONTH(Q$4,0),'Partnerships & Sponsorship'!$E$6:$E$38,">="&Q$4) -> 1
A11: Academy & Education | B11: To be appointed | C11: =COUNTIFS('Academy & Education'!$D$6:$D$27,"<="&EOMONTH(C$4,0),'Academy & Education'!$E$6:$E$27,">="&C$4) -> 0 | D11: =COUNTIFS('Academy & Education'!$D$6:$D$27,"<="&EOMONTH(D$4,0),'Academy & Education'!$E$6:$E$27,">="&D$4) -> 3 | E11: =COUNTIFS('Academy & Education'!$D$6:$D$27,"<="&EOMONTH(E$4,0),'Academy & Education'!$E$6:$E$27,">="&E$4) -> 3 | F11: =COUNTIFS('Academy & Education'!$D$6:$D$27,"<="&EOMONTH(F$4,0),'Academy & Education'!$E$6:$E$27,">="&F$4) -> 3 | G11: =COUNTIFS('Academy & Education'!$D$6:$D$27,"<="&EOMONTH(G$4,0),'Academy & Education'!$E$6:$E$27,">="&G$4) -> 1 | H11: =COUNTIFS('Academy & Education'!$D$6:$D$27,"<="&EOMONTH(H$4,0),'Academy & Education'!$E$6:$E$27,">="&H$4) -> 2 | I11: =COUNTIFS('Academy & Education'!$D$6:$D$27,"<="&EOMONTH(I$4,0),'Academy & Education'!$E$6:$E$27,">="&I$4) -> 3 | J11: =COUNTIFS('Academy & Education'!$D$6:$D$27,"<="&EOMONTH(J$4,0),'Academy & Education'!$E$6:$E$27,">="&J$4) -> 3 | ... Q11: =COUNTIFS('Academy & Education'!$D$6:$D$27,"<="&EOMONTH(Q$4,0),'Academy & Education'!$E$6:$E$27,">="&Q$4) -> 2
A12: Finance & Admin | B12: Executive Director | C12: =COUNTIFS('Finance & Admin'!$D$6:$D$31,"<="&EOMONTH(C$4,0),'Finance & Admin'!$E$6:$E$31,">="&C$4) -> 2 | D12: =COUNTIFS('Finance & Admin'!$D$6:$D$31,"<="&EOMONTH(D$4,0),'Finance & Admin'!$E$6:$E$31,">="&D$4) -> 6 | E12: =COUNTIFS('Finance & Admin'!$D$6:$D$31,"<="&EOMONTH(E$4,0),'Finance & Admin'!$E$6:$E$31,">="&E$4) -> 4 | F12: =COUNTIFS('Finance & Admin'!$D$6:$D$31,"<="&EOMONTH(F$4,0),'Finance & Admin'!$E$6:$E$31,">="&F$4) -> 4 | G12: =COUNTIFS('Finance & Admin'!$D$6:$D$31,"<="&EOMONTH(G$4,0),'Finance & Admin'!$E$6:$E$31,">="&G$4) -> 5 | H12: =COUNTIFS('Finance & Admin'!$D$6:$D$31,"<="&EOMONTH(H$4,0),'Finance & Admin'!$E$6:$E$31,">="&H$4) -> 5 | I12: =COUNTIFS('Finance & Admin'!$D$6:$D$31,"<="&EOMONTH(I$4,0),'Finance & Admin'!$E$6:$E$31,">="&I$4) -> 4 | J12: =COUNTIFS('Finance & Admin'!$D$6:$D$31,"<="&EOMONTH(J$4,0),'Finance & Admin'!$E$6:$E$31,">="&J$4) -> 3 | ... Q12: =COUNTIFS('Finance & Admin'!$D$6:$D$31,"<="&EOMONTH(Q$4,0),'Finance & Admin'!$E$6:$E$31,">="&Q$4) -> 3
A13: Technology | B13: To be appointed | C13: =COUNTIFS(Technology!$D$6:$D$34,"<="&EOMONTH(C$4,0),Technology!$E$6:$E$34,">="&C$4) -> 1 | D13: =COUNTIFS(Technology!$D$6:$D$34,"<="&EOMONTH(D$4,0),Technology!$E$6:$E$34,">="&D$4) -> 3 | E13: =COUNTIFS(Technology!$D$6:$D$34,"<="&EOMONTH(E$4,0),Technology!$E$6:$E$34,">="&E$4) -> 2 | F13: =COUNTIFS(Technology!$D$6:$D$34,"<="&EOMONTH(F$4,0),Technology!$E$6:$E$34,">="&F$4) -> 4 | G13: =COUNTIFS(Technology!$D$6:$D$34,"<="&EOMONTH(G$4,0),Technology!$E$6:$E$34,">="&G$4) -> 5 | H13: =COUNTIFS(Technology!$D$6:$D$34,"<="&EOMONTH(H$4,0),Technology!$E$6:$E$34,">="&H$4) -> 6 | I13: =COUNTIFS(Technology!$D$6:$D$34,"<="&EOMONTH(I$4,0),Technology!$E$6:$E$34,">="&I$4) -> 7 | J13: =COUNTIFS(Technology!$D$6:$D$34,"<="&EOMONTH(J$4,0),Technology!$E$6:$E$34,">="&J$4) -> 7 | ... Q13: =COUNTIFS(Technology!$D$6:$D$34,"<="&EOMONTH(Q$4,0),Technology!$E$6:$E$34,">="&Q$4) -> 1
A14: International & Diplomacy | B14: Abisade (Legal & Diplomacy Director) | C14: =COUNTIFS('International & Diplomacy'!$D$6:$D$27,"<="&EOMONTH(C$4,0),'International & Diplomacy'!$E$6:$E$27,">="&C$4) -> 1 | D14: =COUNTIFS('International & Diplomacy'!$D$6:$D$27,"<="&EOMONTH(D$4,0),'International & Diplomacy'!$E$6:$E$27,">="&D$4) -> 2 | E14: =COUNTIFS('International & Diplomacy'!$D$6:$D$27,"<="&EOMONTH(E$4,0),'International & Diplomacy'!$E$6:$E$27,">="&E$4) -> 2 | F14: =COUNTIFS('International & Diplomacy'!$D$6:$D$27,"<="&EOMONTH(F$4,0),'International & Diplomacy'!$E$6:$E$27,">="&F$4) -> 5 | G14: =COUNTIFS('International & Diplomacy'!$D$6:$D$27,"<="&EOMONTH(G$4,0),'International & Diplomacy'!$E$6:$E$27,">="&G$4) -> 6 | H14: =COUNTIFS('International & Diplomacy'!$D$6:$D$27,"<="&EOMONTH(H$4,0),'International & Diplomacy'!$E$6:$E$27,">="&H$4) -> 4 | I14: =COUNTIFS('International & Diplomacy'!$D$6:$D$27,"<="&EOMONTH(I$4,0),'International & Diplomacy'!$E$6:$E$27,">="&I$4) -> 2 | J14: =COUNTIFS('International & Diplomacy'!$D$6:$D$27,"<="&EOMONTH(J$4,0),'International & Diplomacy'!$E$6:$E$27,">="&J$4) -> 2 | ... Q14: =COUNTIFS('International & Diplomacy'!$D$6:$D$27,"<="&EOMONTH(Q$4,0),'International & Diplomacy'!$E$6:$E$27,">="&Q$4) -> 1
A15: Final 4 weeks (review only) | C15: =IF(AND(EventDate-27<=EOMONTH(C$4,0),EventDate-1>=C$4),"REVIEW","") | D15: =IF(AND(EventDate-27<=EOMONTH(D$4,0),EventDate-1>=D$4),"REVIEW","") | E15: =IF(AND(EventDate-27<=EOMONTH(E$4,0),EventDate-1>=E$4),"REVIEW","") | F15: =IF(AND(EventDate-27<=EOMONTH(F$4,0),EventDate-1>=F$4),"REVIEW","") | G15: =IF(AND(EventDate-27<=EOMONTH(G$4,0),EventDate-1>=G$4),"REVIEW","") | H15: =IF(AND(EventDate-27<=EOMONTH(H$4,0),EventDate-1>=H$4),"REVIEW","") | I15: =IF(AND(EventDate-27<=EOMONTH(I$4,0),EventDate-1>=I$4),"REVIEW","") | J15: =IF(AND(EventDate-27<=EOMONTH(J$4,0),EventDate-1>=J$4),"REVIEW","") | ... Q15: =IF(AND(EventDate-27<=EOMONTH(Q$4,0),EventDate-1>=Q$4),"REVIEW","")
A16: EVENT (proposed) | C16: =IF(AND(EventDate>=C$4,EventDate<=EOMONTH(C$4,0)),"EVENT","") | D16: =IF(AND(EventDate>=D$4,EventDate<=EOMONTH(D$4,0)),"EVENT","") | E16: =IF(AND(EventDate>=E$4,EventDate<=EOMONTH(E$4,0)),"EVENT","") | F16: =IF(AND(EventDate>=F$4,EventDate<=EOMONTH(F$4,0)),"EVENT","") | G16: =IF(AND(EventDate>=G$4,EventDate<=EOMONTH(G$4,0)),"EVENT","") | H16: =IF(AND(EventDate>=H$4,EventDate<=EOMONTH(H$4,0)),"EVENT","") | I16: =IF(AND(EventDate>=I$4,EventDate<=EOMONTH(I$4,0)),"EVENT","") | J16: =IF(AND(EventDate>=J$4,EventDate<=EOMONTH(J$4,0)),"EVENT","") | ... Q16: =IF(AND(EventDate>=Q$4,EventDate<=EOMONTH(Q$4,0)),"EVENT","")
A17: Sponsor-approval gate (Mar 31, 2027) | C17: =IF(AND(DATE(2027,3,31)>=C$4,DATE(2027,3,31)<=EOMONTH(C$4,0)),"GATE","") | D17: =IF(AND(DATE(2027,3,31)>=D$4,DATE(2027,3,31)<=EOMONTH(D$4,0)),"GATE","") | E17: =IF(AND(DATE(2027,3,31)>=E$4,DATE(2027,3,31)<=EOMONTH(E$4,0)),"GATE","") | F17: =IF(AND(DATE(2027,3,31)>=F$4,DATE(2027,3,31)<=EOMONTH(F$4,0)),"GATE","") | G17: =IF(AND(DATE(2027,3,31)>=G$4,DATE(2027,3,31)<=EOMONTH(G$4,0)),"GATE","") | H17: =IF(AND(DATE(2027,3,31)>=H$4,DATE(2027,3,31)<=EOMONTH(H$4,0)),"GATE","") -> GATE | I17: =IF(AND(DATE(2027,3,31)>=I$4,DATE(2027,3,31)<=EOMONTH(I$4,0)),"GATE","") | J17: =IF(AND(DATE(2027,3,31)>=J$4,DATE(2027,3,31)<=EOMONTH(J$4,0)),"GATE","") | ... Q17: =IF(AND(DATE(2027,3,31)>=Q$4,DATE(2027,3,31)<=EOMONTH(Q$4,0)),"GATE","")
A19: How to read: each number is how many tasks are active in that department that month (a task is active from its start to its planned finish). Darker blue = busier. Nothing is active after Sep 30, 2027 except review, rehearsal, contingency and after-event work.

Sheet Milestone shifts
A1: Milestone shifts: the old plan (finals Mar 13, 2027) rebuilt around Nov 11, 2027
A2: Source for the old column: NISMCAA_10th_Edition_Plan.docx, section D2 (draft Oct 13, 2026). Its Mar 13, 2027 date is superseded by Nov 11, 2027 (PROPOSED; subject to sponsor approval). Old dates in that plan were suggestions.
A4: # | B4: Old milestone (old plan D2) | C4: Old timing | D4: New milestone | E4: New planned date | F4: Shift | G4: Why it moved
A5: 1 | B5: Oct 2026 (now): confirm legal status, FB/IG audit, claim handles, set the budget, shortlist venues | C5: Oct 2026 | D5: Plan approved; legal status and budget work started | E5: 46374 | F5: Same start | G5: Start unchanged (now). Each item now has a finish date: gap list Nov 6, handles Nov 13, venue shortlist Dec 18, 2026.
A6: 2 | B6: Early Nov 2026: send sponsor packs to the top 15 leads | C6: Early Nov 2026 | D6: Sponsor packs sent to the top 15 leads | E6: 46374 | F6: +7 weeks (about +2 months) | G6: About 6 weeks later than the old draft, because the funding plan builds the deck first (days 15-45, to Nov 27). The event is 8 months later, so there is no pressure to send earlier than a good deck.
A7: 3 | B7: Early Nov 2026: book the venue (4 months before the event) | C7: Early Nov 2026 | D7: Venue booked in writing | E7: =EventDate-195 -> 46507 | F7: +26 weeks (about +6 months) | G7: Booked 6.5 months before the event instead of 4. A provisional hold is placed by Mar 12, 2027. The written booking waits for the Mar 31 sponsor-approval gate. Shortlist and quotes come first.
A8: 4 | B8: Early Nov 2026: approach the Lagos Ministry for endorsement | C8: Early Nov 2026 | D8: Lagos Ministry endorsement approached | E8: 46416 | F8: +13 weeks (about +3 months) | G8: Moved to Dec 2026-Jan 2027 so the sponsor pack and a venue shortlist go with the request.
A9: 5 | B9: Mid-Nov 2026: choose theme, announce, open school registration | C9: Mid-Nov 2026 | D9: Theme chosen; 10th Edition announced; registration open | E9: 46398 | F9: +8 weeks (about +2 months) | G9: Theme by Dec 11, 2026. Announcement Jan 11, 2027 (10 months before the event) so the date wording is settled first. Registration stays open from Nov 16, 2026 per the old plan.
A10: 6 | B10: Dec 2026: recruit judges and the auditor; choose a digital scoring tool; press briefing | C10: Dec 2026 | D10: Rulebook frozen; judges and auditor recruited; scoring tool chosen | E10: 46374 | F10: +2 weeks (about +1 months) | G10: Rulebook frozen Dec 18, 2026 (Jury plan). Judge recruitment opens Jan 2027, the course runs Apr-May, certificates Jun 18, auditor by Apr 30, 2027, as in the Jury plan. Press briefing Jan 22.
A11: 7 | B11: Jan 2027 (election month): keep campaign going; sponsor follow-ups and contracts | C11: Jan 2027 | D11: Sponsor contracts and online campaign | E11: =EventDate-72 -> 46630 | F11: +33 weeks (about +8 months) | G11: Follow-ups Jan 12; headline and gold sponsors in writing by Jun 30; every agreement by Aug 31, 2027. Online-only activity around Jan 16 and Feb 6, 2027 is kept.
A12: 8 | B12: (not in the old plan) | C12: - | D12: Sponsor-approval gate: date confirmed or changed | E12: 46477 | F12: New | G12: New gate, because the date is proposed and subject to sponsor approval. If the date moves, change one cell and every later date moves with it.
A13: 9 | B13: End Jan 2027: registration and nominations close | C13: End Jan 2027 | D13: Registration and Academic Award nominations close | E13: =EventDate-134 -> 46568 | F13: +22 weeks (about +5 months) | G13: Closes 4.5 months before the event (old plan: 6 weeks before). Qualifying rounds then have July and August.
A14: 10 | B14: Early-mid Feb 2027: preliminaries and a dry run of scoring | C14: Early-mid Feb 2027 | D14: Qualifying rounds and scoring dry run | E14: =EventDate-76 -> 46626 | F14: +28 weeks (about +7 months) | G14: Dry run is the mock round (Jun 25). Qualifying rounds Jul 5-Aug 27, 2027, as the Jury plan says Jul-Sep, pulled to finish early.
A15: 11 | B15: Late Feb 2027: finalists announced, technical rehearsal plan, run sheet, accreditation | C15: Late Feb 2027 | D15: Finalists announced; technical rehearsal plan and run sheet; media accreditation | E15: =EventDate-48 -> 46654 | F15: +30 weeks (about +7 months) | G15: Finalists Sep 10, 2027. Rehearsal plan and run sheet Sep 24. Accreditation closes Sep 30.
A16: 12 | B16: 1-12 Mar 2027: final rehearsals, judge briefing, mock scoring audit, program printing | C16: Last 12 days | D16: Program printing, judge briefing, mock scoring audit | E16: =EventDate-42 -> 46660 | F16: +30 weeks (about +7 months) | G16: These were in the last 12 days. They now finish by Sep 30, 2027 (printing, mock audit and rehearsal #1). The judges' final briefing and rehearsal #2 are in the review window, as review only.
A17: 13 | B17: (not in the old plan) | C17: - | D17: ALL WORK DONE (planned) | E17: =EventDate-42 -> 46660 | F17: New | G17: John's rule. Every build task finishes by Sep 30, 2027. The hard limit for every task is Oct 14, 2027 (4 weeks before the event).
A18: 14 | B18: (not in the old plan) | C18: - | D18: Hard limit: all work finished | E18: =EventDate-28 -> 46674 | F18: New | G18: Event date minus 28 days. After this: no new tasks.
A19: 15 | B19: (not in the old plan) | C19: - | D19: Review, rehearsal and contingency window | E19: =EventDate-27 -> 46675 | F19: New | G19: Oct 15 to Nov 10, 2027: review, rehearsal and contingency only.
A20: 16 | B20: 13 Mar 2027 (backup Mar 18) | C20: 13 Mar 2027 | D20: 10th Edition Grand Finale (PROPOSED) | E20: =EventDate -> 46702 | F20: +35 weeks (about +8 months) | G20: Replaced by Nov 11, 2027 (John, Oct 26, 2026), a Thursday. Subject to sponsor approval; may still change. The old reasons (elections, Ramadan) no longer apply to this date; the school calendar check is a task in Event Operations.
A21: 17 | B21: Within 7 days after | C21: Within 7 days | D21: Results and score summary published; sponsor reports | E21: =EventDate+7 -> 46709 | F21: +35 weeks (about +8 months) | G21: Same rule: 7 days after the event.
A22: 18 | B22: Within 60 days after | C22: Within 60 days | D22: Impact report and audited event accounts | E22: =EventDate+60 -> 46762 | F22: +35 weeks (about +8 months) | G22: Same rule: within 60 days (Jan 10, 2028). Planned finish Jan 7, 2028.

Sheet Office of the Founder
A1: Office of the Founder - 10th Edition action plan
A2: PROPOSED: Nov 11, 2027 (Thursday). Subject to sponsor approval; may still change. (John, Oct 26, 2026)
A3: Lead: Founder & President (Olushola John Adebowale) | D3: Tasks | E3: =COUNT(A6:A26) -> 16 | F3: Done | G3: =COUNTIF(G6:G26,"Done") -> 0 | H3: RED | I3: =COUNTIF(L6:L26,"RED") -> 0 | J3: AMBER | K3: =COUNTIF(L6:L26,"AMBER") -> 0 | L3: Behind: | M3: {=IF(I3+K3=0,"Nothing behind schedule",_xlfn.TEXTJOIN(", ",TRUE(),IF((L6:L26="RED")+(L6:L26="AMBER"),"#"&A6:A26,"")))} -> Nothing behind schedule
A4: Flag rule: RED if the deadline has passed and the task is not done, or 30+ points behind the time used. AMBER 15-29 points. GREEN otherwise. GREY if there is no deadline or the task is on hold. Shaded rows are the final 4 weeks: review, rehearsal and contingency only.
A5: No. | B5: Task | C5: Owner | D5: Start | E5: Deadline (planned finish) | F5: Hard limit (+2 weeks) | G5: Status | H5: % progress | I5: Days left | J5: Time used | K5: Points behind | L5: Flag | M5: Notes
A6: PHASE 1 - FOUNDATIONS: tasks that start Oct 26 - Dec 31, 2026
A7: 1 | B7: Confirm the eligibility gap list: legal status (CAC), U.S. status and accounts | C7: John (Founder) | D7: 46321 | E7: 46332 | F7: =E7+14 -> 46346 | G7: Not started | H7: 0 | I7: =IF(E7="","",IF(G7="Done","Done",E7-TODAY())) -> 11 | J7: =IF(OR(D7="",E7=""),"",IF(E7>D7,MAX(0,MIN(1,(TODAY()-D7)/(E7-D7))),IF(TODAY()>=E7,1,0))) -> 0 | K7: =IF(J7="","",ROUND(J7*100-H7*100,0)) -> 0 | L7: =IF(OR(D7="",E7=""),"GREY",IF(G7="On hold","GREY",IF(G7="Done","GREEN",IF(E7<TODAY(),"RED",IF(K7>=30,"RED",IF(K7>=15,"AMBER","GREEN")))))) -> GREEN | M7: Source: Funding plan section 7 (days 1-14) and 10th Edition plan D2 ('Confirm legal status'). The funding plan wanted this by Oct 28; set to Nov 6 because nothing has started.
A8: 2 | B8: Decide the public wording for the date: '2027 - Get ready!' or 'proposed Nov 11, 2027' | C8: John (Founder) | D8: 46321 | E8: 46332 | F8: =E8+14 -> 46346 | G8: Not started | H8: 0 | I8: =IF(E8="","",IF(G8="Done","Done",E8-TODAY())) -> 11 | J8: =IF(OR(D8="",E8=""),"",IF(E8>D8,MAX(0,MIN(1,(TODAY()-D8)/(E8-D8))),IF(TODAY()>=E8,1,0))) -> 0 | K8: =IF(J8="","",ROUND(J8*100-H8*100,0)) -> 0 | L8: =IF(OR(D8="",E8=""),"GREY",IF(G8="On hold","GREY",IF(G8="Done","GREEN",IF(E8<TODAY(),"RED",IF(K8>=30,"RED",IF(K8>=15,"AMBER","GREEN")))))) -> GREEN | M8: Source: DECISIONS_CHECKLIST F17 (open ruling). Public pages must say PROPOSED until the date is confirmed.
A9: 3 | B9: Approve the Jury System plan, this action plan and the open decisions list | C9: John (Founder) | D9: 46321 | E9: 46346 | F9: =E9+14 -> 46360 | G9: Not started | H9: 0 | I9: =IF(E9="","",IF(G9="Done","Done",E9-TODAY())) -> 25 | J9: =IF(OR(D9="",E9=""),"",IF(E9>D9,MAX(0,MIN(1,(TODAY()-D9)/(E9-D9))),IF(TODAY()>=E9,1,0))) -> 0 | K9: =IF(J9="","",ROUND(J9*100-H9*100,0)) -> 0 | L9: =IF(OR(D9="",E9=""),"GREY",IF(G9="On hold","GREY",IF(G9="Done","GREEN",IF(E9<TODAY(),"RED",IF(K9>=30,"RED",IF(K9>=15,"AMBER","GREEN")))))) -> GREEN | M9: Source: Jury System plan section 23 ('Nov 2026: John approves this plan'). Approving this action plan is Suggested.
A10: 4 | B10: Choose the 10th Edition theme (options in plan D3) | C10: John (Founder) | D10: 46328 | E10: 46367 | F10: =E10+14 -> 46381 | G10: Not started | H10: 0 | I10: =IF(E10="","",IF(G10="Done","Done",E10-TODAY())) -> 46 | J10: =IF(OR(D10="",E10=""),"",IF(E10>D10,MAX(0,MIN(1,(TODAY()-D10)/(E10-D10))),IF(TODAY()>=E10,1,0))) -> 0 | K10: =IF(J10="","",ROUND(J10*100-H10*100,0)) -> 0 | L10: =IF(OR(D10="",E10=""),"GREY",IF(G10="On hold","GREY",IF(G10="Done","GREEN",IF(E10<TODAY(),"RED",IF(K10>=30,"RED",IF(K10>=15,"AMBER","GREEN")))))) -> GREEN | M10: Source: 10th Edition plan D2 ('Mid-Nov 2026: choose the theme') and D3 theme ideas.
A11: 5 | B11: Appoint heads for the 7 departments that have no lead yet (after volunteer assessment) | C11: John (Founder) | D11: 46328 | E11: 46374 | F11: =E11+14 -> 46388 | G11: Not started | H11: 0 | I11: =IF(E11="","",IF(G11="Done","Done",E11-TODAY())) -> 53 | J11: =IF(OR(D11="",E11=""),"",IF(E11>D11,MAX(0,MIN(1,(TODAY()-D11)/(E11-D11))),IF(TODAY()>=E11,1,0))) -> 0 | K11: =IF(J11="","",ROUND(J11*100-H11*100,0)) -> 0 | L11: =IF(OR(D11="",E11=""),"GREY",IF(G11="On hold","GREY",IF(G11="Done","GREEN",IF(E11<TODAY(),"RED",IF(K11>=30,"RED",IF(K11>=15,"AMBER","GREEN")))))) -> GREEN | M11: Source: Volunteer Roles file ('heads appointed after a few weeks of assessing volunteer contributions'). Dependent: every other department sheet.
A12: 6 | B12: Monthly plan review with all department heads (last Monday of each month) | C12: John (Founder) | D12: 46356 | E12: =EventDate-45 -> 46657 | F12: =E12+14 -> 46671 | G12: Not started | H12: 0 | I12: =IF(E12="","",IF(G12="Done","Done",E12-TODAY())) -> 336 | J12: =IF(OR(D12="",E12=""),"",IF(E12>D12,MAX(0,MIN(1,(TODAY()-D12)/(E12-D12))),IF(TODAY()>=E12,1,0))) -> 0 | K12: =IF(J12="","",ROUND(J12*100-H12*100,0)) -> 0 | L12: =IF(OR(D12="",E12=""),"GREY",IF(G12="On hold","GREY",IF(G12="Done","GREEN",IF(E12<TODAY(),"RED",IF(K12>=30,"RED",IF(K12>=15,"AMBER","GREEN")))))) -> GREEN | M12: Suggested. Use the Meeting Room action plan sheets; any RED or AMBER flag is discussed first.
A13: 7 | B13: Record a short Founder video: why NISMCAA turns 10 | C13: John (Founder) | D13: 46357 | E13: 46395 | F13: =E13+14 -> 46409 | G13: Not started | H13: 0 | I13: =IF(E13="","",IF(G13="Done","Done",E13-TODAY())) -> 74 | J13: =IF(OR(D13="",E13=""),"",IF(E13>D13,MAX(0,MIN(1,(TODAY()-D13)/(E13-D13))),IF(TODAY()>=E13,1,0))) -> 0 | K13: =IF(J13="","",ROUND(J13*100-H13*100,0)) -> 0 | L13: =IF(OR(D13="",E13=""),"GREY",IF(G13="On hold","GREY",IF(G13="Done","GREEN",IF(E13<TODAY(),"RED",IF(K13>=30,"RED",IF(K13>=15,"AMBER","GREEN")))))) -> GREEN | M13: Source: 10th Edition plan A4 calendar day 5 (founder video). Wording must follow the date decision above.
A14: PHASE 2 - BUILD AND RECRUIT: tasks that start Jan 1 - Jun 30, 2027
A15: 8 | B15: Sponsor approval gate: confirm or change the Nov 11, 2027 date using sponsor feedback | C15: John (Founder) | D15: 46391 | E15: 46477 | F15: =E15+14 -> 46491 | G15: Not started | H15: 0 | I15: =IF(E15="","",IF(G15="Done","Done",E15-TODAY())) -> 156 | J15: =IF(OR(D15="",E15=""),"",IF(E15>D15,MAX(0,MIN(1,(TODAY()-D15)/(E15-D15))),IF(TODAY()>=E15,1,0))) -> 0 | K15: =IF(J15="","",ROUND(J15*100-H15*100,0)) -> 0 | L15: =IF(OR(D15="",E15=""),"GREY",IF(G15="On hold","GREY",IF(G15="Done","GREEN",IF(E15<TODAY(),"RED",IF(K15>=30,"RED",IF(K15>=15,"AMBER","GREEN")))))) -> GREEN | M15: Suggested. If the date changes, change the Event date cell on 'All departments'; every date after Mar 31, 2027 moves with it. Re-check the 4-week rule.
A16: 9 | B16: Founder-level meetings with the headline sponsor and key partners | C16: John (Founder) | D16: 46398 | E16: =EventDate-134 -> 46568 | F16: =E16+14 -> 46582 | G16: Not started | H16: 0 | I16: =IF(E16="","",IF(G16="Done","Done",E16-TODAY())) -> 247 | J16: =IF(OR(D16="",E16=""),"",IF(E16>D16,MAX(0,MIN(1,(TODAY()-D16)/(E16-D16))),IF(TODAY()>=E16,1,0))) -> 0 | K16: =IF(J16="","",ROUND(J16*100-H16*100,0)) -> 0 | L16: =IF(OR(D16="",E16=""),"GREY",IF(G16="On hold","GREY",IF(G16="Done","GREEN",IF(E16<TODAY(),"RED",IF(K16>=30,"RED",IF(K16>=15,"AMBER","GREEN")))))) -> GREEN | M16: Source: Funding plan section 7 (sponsor meetings), extended. Suggested timing.
A17: 10 | B17: Approve the VIP, patron and dignitary guest list | C17: To be appointed (Protocol & Guest Liaison) | D17: =EventDate-163 -> 46539 | E17: =EventDate-76 -> 46626 | F17: =E17+14 -> 46640 | G17: Not started | H17: 0 | I17: =IF(E17="","",IF(G17="Done","Done",E17-TODAY())) -> 305 | J17: =IF(OR(D17="",E17=""),"",IF(E17>D17,MAX(0,MIN(1,(TODAY()-D17)/(E17-D17))),IF(TODAY()>=E17,1,0))) -> 0 | K17: =IF(J17="","",ROUND(J17*100-H17*100,0)) -> 0 | L17: =IF(OR(D17="",E17=""),"GREY",IF(G17="On hold","GREY",IF(G17="Done","GREEN",IF(E17<TODAY(),"RED",IF(K17>=30,"RED",IF(K17>=15,"AMBER","GREEN")))))) -> GREEN | M17: Suggested. Role from Volunteer Roles file (Protocol & Guest Liaison Officer).
A18: PHASE 3 - RUN AND PREPARE: tasks that start Jul 1 - Sep 30, 2027 (all finish by Sep 30; hard limit Oct 14)
A19: 11 | B19: Send invitations to patrons, VIPs and dignitaries | C19: To be appointed (Correspondence Assistant) | D19: =EventDate-101 -> 46601 | E19: =EventDate-62 -> 46640 | F19: =E19+14 -> 46654 | G19: Not started | H19: 0 | I19: =IF(E19="","",IF(G19="Done","Done",E19-TODAY())) -> 319 | J19: =IF(OR(D19="",E19=""),"",IF(E19>D19,MAX(0,MIN(1,(TODAY()-D19)/(E19-D19))),IF(TODAY()>=E19,1,0))) -> 0 | K19: =IF(J19="","",ROUND(J19*100-H19*100,0)) -> 0 | L19: =IF(OR(D19="",E19=""),"GREY",IF(G19="On hold","GREY",IF(G19="Done","GREEN",IF(E19<TODAY(),"RED",IF(K19>=30,"RED",IF(K19>=15,"AMBER","GREEN")))))) -> GREEN | M19: Suggested. Role from Volunteer Roles file (Correspondence & Communications Assistant).
A20: 12 | B20: Founder sign-off: every department head confirms all build tasks are done | C20: John (Founder) | D20: =EventDate-52 -> 46650 | E20: =EventDate-42 -> 46660 | F20: =E20+14 -> 46674 | G20: Not started | H20: 0 | I20: =IF(E20="","",IF(G20="Done","Done",E20-TODAY())) -> 339 | J20: =IF(OR(D20="",E20=""),"",IF(E20>D20,MAX(0,MIN(1,(TODAY()-D20)/(E20-D20))),IF(TODAY()>=E20,1,0))) -> 0 | K20: =IF(J20="","",ROUND(J20*100-H20*100,0)) -> 0 | L20: =IF(OR(D20="",E20=""),"GREY",IF(G20="On hold","GREY",IF(G20="Done","GREEN",IF(E20<TODAY(),"RED",IF(K20>=30,"RED",IF(K20>=15,"AMBER","GREEN")))))) -> GREEN | M20: John's rule: all work done at least 4 weeks before the event. Hard limit Oct 14, 2027.
A21: PHASE 4 - FINAL 4 WEEKS (Oct 15 - Nov 10, 2027): REVIEW, REHEARSAL AND CONTINGENCY ONLY. NO NEW TASKS.
A22: 13 | B22: Final go / no-go meeting with all department heads | C22: John (Founder) | D22: =EventDate-27 -> 46675 | E22: =EventDate-20 -> 46682 | F22: =E22 -> 46682 | G22: Not started | H22: 0 | I22: =IF(E22="","",IF(G22="Done","Done",E22-TODAY())) -> 361 | J22: =IF(OR(D22="",E22=""),"",IF(E22>D22,MAX(0,MIN(1,(TODAY()-D22)/(E22-D22))),IF(TODAY()>=E22,1,0))) -> 0 | K22: =IF(J22="","",ROUND(J22*100-H22*100,0)) -> 0 | L22: =IF(OR(D22="",E22=""),"GREY",IF(G22="On hold","GREY",IF(G22="Done","GREEN",IF(E22<TODAY(),"RED",IF(K22>=30,"RED",IF(K22>=15,"AMBER","GREEN")))))) -> GREEN | M22: Review only. No new tasks may be added after Oct 14, 2027.
A23: 14 | B23: Protocol rehearsal for VIPs, patrons and guests (seating, welcome, introductions) | C23: To be appointed (Protocol & Guest Liaison) | D23: =EventDate-17 -> 46685 | E23: =EventDate-6 -> 46696 | F23: =E23 -> 46696 | G23: Not started | H23: 0 | I23: =IF(E23="","",IF(G23="Done","Done",E23-TODAY())) -> 375 | J23: =IF(OR(D23="",E23=""),"",IF(E23>D23,MAX(0,MIN(1,(TODAY()-D23)/(E23-D23))),IF(TODAY()>=E23,1,0))) -> 0 | K23: =IF(J23="","",ROUND(J23*100-H23*100,0)) -> 0 | L23: =IF(OR(D23="",E23=""),"GREY",IF(G23="On hold","GREY",IF(G23="Done","GREEN",IF(E23<TODAY(),"RED",IF(K23>=30,"RED",IF(K23>=15,"AMBER","GREEN")))))) -> GREEN | M23: Review/rehearsal only. Suggested.
A24: PHASE 5 - EVENT DAY AND AFTER (from Nov 11, 2027)
A25: 15 | B25: Thank-you letters to patrons, guests, sponsors and volunteers | C25: John (Founder) | D25: =EventDate+1 -> 46703 | E25: =EventDate+8 -> 46710 | F25: =E25+14 -> 46724 | G25: Not started | H25: 0 | I25: =IF(E25="","",IF(G25="Done","Done",E25-TODAY())) -> 389 | J25: =IF(OR(D25="",E25=""),"",IF(E25>D25,MAX(0,MIN(1,(TODAY()-D25)/(E25-D25))),IF(TODAY()>=E25,1,0))) -> 0 | K25: =IF(J25="","",ROUND(J25*100-H25*100,0)) -> 0 | L25: =IF(OR(D25="",E25=""),"GREY",IF(G25="On hold","GREY",IF(G25="Done","GREEN",IF(E25<TODAY(),"RED",IF(K25>=30,"RED",IF(K25>=15,"AMBER","GREEN")))))) -> GREEN | M25: Suggested. Source: 10th Edition plan D2 (thank-you posts and sponsor reports).
A26: 16 | B26: Debrief and lessons-learned report from every department to the Founder | C26: John (Founder) | D26: =EventDate+4 -> 46706 | E26: =EventDate+29 -> 46731 | F26: =E26+14 -> 46745 | G26: Not started | H26: 0 | I26: =IF(E26="","",IF(G26="Done","Done",E26-TODAY())) -> 410 | J26: =IF(OR(D26="",E26=""),"",IF(E26>D26,MAX(0,MIN(1,(TODAY()-D26)/(E26-D26))),IF(TODAY()>=E26,1,0))) -> 0 | K26: =IF(J26="","",ROUND(J26*100-H26*100,0)) -> 0 | L26: =IF(OR(D26="",E26=""),"GREY",IF(G26="On hold","GREY",IF(G26="Done","GREEN",IF(E26<TODAY(),"RED",IF(K26>=30,"RED",IF(K26>=15,"AMBER","GREEN")))))) -> GREEN | M26: Suggested. Mirrors the debrief step in the Academy launch plan (T+1 week).

Sheet Programs & Competition
A1: Programs & Competition - 10th Edition action plan
A2: PROPOSED: Nov 11, 2027 (Thursday). Subject to sponsor approval; may still change. (John, Oct 26, 2026)
A3: Lead: Project Manager / Secretariat (Chief Judge: Dr Teemac Omotshola Iseli) | D3: Tasks | E3: =COUNT(A6:A37) -> 27 | F3: Done | G3: =COUNTIF(G6:G37,"Done") -> 0 | H3: RED | I3: =COUNTIF(L6:L37,"RED") -> 0 | J3: AMBER | K3: =COUNTIF(L6:L37,"AMBER") -> 0 | L3: Behind: | M3: {=IF(I3+K3=0,"Nothing behind schedule",_xlfn.TEXTJOIN(", ",TRUE(),IF((L6:L37="RED")+(L6:L37="AMBER"),"#"&A6:A37,"")))} -> Nothing behind schedule
A4: Flag rule: RED if the deadline has passed and the task is not done, or 30+ points behind the time used. AMBER 15-29 points. GREEN otherwise. GREY if there is no deadline or the task is on hold. Shaded rows are the final 4 weeks: review, rehearsal and contingency only.
A5: No. | B5: Task | C5: Owner | D5: Start | E5: Deadline (planned finish) | F5: Hard limit (+2 weeks) | G5: Status | H5: % progress | I5: Days left | J5: Time used | K5: Points behind | L5: Flag | M5: Notes
A6: PHASE 1 - FOUNDATIONS: tasks that start Oct 26 - Dec 31, 2026
A7: 1 | B7: School registration window open: check each school entry, answer questions | C7: Project Manager | D7: 46342 | E7: =EventDate-134 -> 46568 | F7: =E7+14 -> 46582 | G7: Not started | H7: 0 | I7: =IF(E7="","",IF(G7="Done","Done",E7-TODAY())) -> 247 | J7: =IF(OR(D7="",E7=""),"",IF(E7>D7,MAX(0,MIN(1,(TODAY()-D7)/(E7-D7))),IF(TODAY()>=E7,1,0))) -> 0 | K7: =IF(J7="","",ROUND(J7*100-H7*100,0)) -> 0 | L7: =IF(OR(D7="",E7=""),"GREY",IF(G7="On hold","GREY",IF(G7="Done","GREEN",IF(E7<TODAY(),"RED",IF(K7>=30,"RED",IF(K7>=15,"AMBER","GREEN")))))) -> GREEN | M7: Source: 10th Edition plan D2 (registration opens mid-Nov 2026). Closing date moved from end Jan 2027 to Jun 30, 2027 - see Milestone shifts. Public date wording follows John's decision.
A8: 2 | B8: Draft rulebook v2027.1: rubric, scoring algorithms, vote rules, aid statuses, penalty ranges, tie, rounding and appeal rules | C8: Chief Judge | D8: 46349 | E8: 46360 | F8: =E8+14 -> 46374 | G8: Not started | H8: 0 | I8: =IF(E8="","",IF(G8="Done","Done",E8-TODAY())) -> 39 | J8: =IF(OR(D8="",E8=""),"",IF(E8>D8,MAX(0,MIN(1,(TODAY()-D8)/(E8-D8))),IF(TODAY()>=E8,1,0))) -> 0 | K8: =IF(J8="","",ROUND(J8*100-H8*100,0)) -> 0 | L8: =IF(OR(D8="",E8=""),"GREY",IF(G8="On hold","GREY",IF(G8="Done","GREEN",IF(E8<TODAY(),"RED",IF(K8>=30,"RED",IF(K8>=15,"AMBER","GREEN")))))) -> GREEN | M8: Source: Jury System plan section 23 (Dec 2026). Values marked 'John to confirm' in section 24 stay open until John decides.
A9: 3 | B9: Approve and freeze rulebook v2027.1 (before any entries are scored) | C9: John (Founder) | D9: 46363 | E9: 46374 | F9: =E9+14 -> 46388 | G9: Not started | H9: 0 | I9: =IF(E9="","",IF(G9="Done","Done",E9-TODAY())) -> 53 | J9: =IF(OR(D9="",E9=""),"",IF(E9>D9,MAX(0,MIN(1,(TODAY()-D9)/(E9-D9))),IF(TODAY()>=E9,1,0))) -> 0 | K9: =IF(J9="","",ROUND(J9*100-H9*100,0)) -> 0 | L9: =IF(OR(D9="",E9=""),"GREY",IF(G9="On hold","GREY",IF(G9="Done","GREEN",IF(E9<TODAY(),"RED",IF(K9>=30,"RED",IF(K9>=15,"AMBER","GREEN")))))) -> GREEN | M9: Source: Jury System plan section 23 ('approved and frozen before entries open').
A10: PHASE 2 - BUILD AND RECRUIT: tasks that start Jan 1 - Jun 30, 2027
A11: 4 | B11: Publish the rubric and rules to all schools | C11: Project Manager | D11: 46391 | E11: 46416 | F11: =E11+14 -> 46430 | G11: Not started | H11: 0 | I11: =IF(E11="","",IF(G11="Done","Done",E11-TODAY())) -> 95 | J11: =IF(OR(D11="",E11=""),"",IF(E11>D11,MAX(0,MIN(1,(TODAY()-D11)/(E11-D11))),IF(TODAY()>=E11,1,0))) -> 0 | K11: =IF(J11="","",ROUND(J11*100-H11*100,0)) -> 0 | L11: =IF(OR(D11="",E11=""),"GREY",IF(G11="On hold","GREY",IF(G11="Done","GREEN",IF(E11<TODAY(),"RED",IF(K11>=30,"RED",IF(K11>=15,"AMBER","GREEN")))))) -> GREEN | M11: Source: 10th Edition plan D5 (published rubric before the competition).
A12: 5 | B12: Jury applications open (agreement tick box, no referees) | C12: Chief Judge | D12: 46398 | E12: 46477 | F12: =E12+14 -> 46491 | G12: Not started | H12: 0 | I12: =IF(E12="","",IF(G12="Done","Done",E12-TODAY())) -> 156 | J12: =IF(OR(D12="",E12=""),"",IF(E12>D12,MAX(0,MIN(1,(TODAY()-D12)/(E12-D12))),IF(TODAY()>=E12,1,0))) -> 0 | K12: =IF(J12="","",ROUND(J12*100-H12*100,0)) -> 0 | L12: =IF(OR(D12="",E12=""),"GREY",IF(G12="On hold","GREY",IF(G12="Done","GREEN",IF(E12<TODAY(),"RED",IF(K12>=30,"RED",IF(K12>=15,"AMBER","GREEN")))))) -> GREEN | M12: Source: Jury System plan section 23 (Jan 2027) and Volunteer Roles vetting rules.
A13: 6 | B13: Record benchmark performances and reference-score them | C13: Chief Judge | D13: 46419 | E13: 46477 | F13: =E13+14 -> 46491 | G13: Not started | H13: 0 | I13: =IF(E13="","",IF(G13="Done","Done",E13-TODAY())) -> 156 | J13: =IF(OR(D13="",E13=""),"",IF(E13>D13,MAX(0,MIN(1,(TODAY()-D13)/(E13-D13))),IF(TODAY()>=E13,1,0))) -> 0 | K13: =IF(J13="","",ROUND(J13*100-H13*100,0)) -> 0 | L13: =IF(OR(D13="",E13=""),"GREY",IF(G13="On hold","GREY",IF(G13="Done","GREEN",IF(E13<TODAY(),"RED",IF(K13>=30,"RED",IF(K13>=15,"AMBER","GREEN")))))) -> GREEN | M13: Source: Jury System plan section 23 (Feb-Mar 2027).
A14: 7 | B14: Build the Judges' Course and tests (80% pass; attempt counter) | C14: Chief Judge | D14: 46419 | E14: 46477 | F14: =E14+14 -> 46491 | G14: Not started | H14: 0 | I14: =IF(E14="","",IF(G14="Done","Done",E14-TODAY())) -> 156 | J14: =IF(OR(D14="",E14=""),"",IF(E14>D14,MAX(0,MIN(1,(TODAY()-D14)/(E14-D14))),IF(TODAY()>=E14,1,0))) -> 0 | K14: =IF(J14="","",ROUND(J14*100-H14*100,0)) -> 0 | L14: =IF(OR(D14="",E14=""),"GREY",IF(G14="On hold","GREY",IF(G14="Done","GREEN",IF(E14<TODAY(),"RED",IF(K14>=30,"RED",IF(K14>=15,"AMBER","GREEN")))))) -> GREEN | M14: Source: Jury System plan sections 7 and 23. Time between attempts: John to confirm.
A15: 8 | B15: Judges' Course cohort 1: course, tests and interviews | C15: Chief Judge | D15: =EventDate-213 -> 46489 | E15: =EventDate-167 -> 46535 | F15: =E15+14 -> 46549 | G15: Not started | H15: 0 | I15: =IF(E15="","",IF(G15="Done","Done",E15-TODAY())) -> 214 | J15: =IF(OR(D15="",E15=""),"",IF(E15>D15,MAX(0,MIN(1,(TODAY()-D15)/(E15-D15))),IF(TODAY()>=E15,1,0))) -> 0 | K15: =IF(J15="","",ROUND(J15*100-H15*100,0)) -> 0 | L15: =IF(OR(D15="",E15=""),"GREY",IF(G15="On hold","GREY",IF(G15="Done","GREEN",IF(E15<TODAY(),"RED",IF(K15>=30,"RED",IF(K15>=15,"AMBER","GREEN")))))) -> GREEN | M15: Source: Jury System plan section 23 (Apr-May 2027).
A16: 9 | B16: Issue judge certificates; name reserve judges | C16: Chief Judge | D16: =EventDate-163 -> 46539 | E16: =EventDate-146 -> 46556 | F16: =E16+14 -> 46570 | G16: Not started | H16: 0 | I16: =IF(E16="","",IF(G16="Done","Done",E16-TODAY())) -> 235 | J16: =IF(OR(D16="",E16=""),"",IF(E16>D16,MAX(0,MIN(1,(TODAY()-D16)/(E16-D16))),IF(TODAY()>=E16,1,0))) -> 0 | K16: =IF(J16="","",ROUND(J16*100-H16*100,0)) -> 0 | L16: =IF(OR(D16="",E16=""),"GREY",IF(G16="On hold","GREY",IF(G16="Done","GREEN",IF(E16<TODAY(),"RED",IF(K16>=30,"RED",IF(K16>=15,"AMBER","GREEN")))))) -> GREEN | M16: Source: Jury System plan sections 7.3, 11.4 and 23 (Jun 2027).
A17: 10 | B17: Mock round using 9th Edition data: first full test of the scoring workflow | C17: Project Manager | D17: =EventDate-163 -> 46539 | E17: =EventDate-139 -> 46563 | F17: =E17+14 -> 46577 | G17: Not started | H17: 0 | I17: =IF(E17="","",IF(G17="Done","Done",E17-TODAY())) -> 242 | J17: =IF(OR(D17="",E17=""),"",IF(E17>D17,MAX(0,MIN(1,(TODAY()-D17)/(E17-D17))),IF(TODAY()>=E17,1,0))) -> 0 | K17: =IF(J17="","",ROUND(J17*100-H17*100,0)) -> 0 | L17: =IF(OR(D17="",E17=""),"GREY",IF(G17="On hold","GREY",IF(G17="Done","GREEN",IF(E17<TODAY(),"RED",IF(K17>=30,"RED",IF(K17>=15,"AMBER","GREEN")))))) -> GREEN | M17: Source: Jury System plan section 23 (Jun 2027) and plan D5 ('dry run'). Joint with Technology.
A18: 11 | B18: Judge agreements signed by every appointed judge | C18: Chief Judge | D18: =EventDate-157 -> 46545 | E18: =EventDate-134 -> 46568 | F18: =E18+14 -> 46582 | G18: Not started | H18: 0 | I18: =IF(E18="","",IF(G18="Done","Done",E18-TODAY())) -> 247 | J18: =IF(OR(D18="",E18=""),"",IF(E18>D18,MAX(0,MIN(1,(TODAY()-D18)/(E18-D18))),IF(TODAY()>=E18,1,0))) -> 0 | K18: =IF(J18="","",ROUND(J18*100-H18*100,0)) -> 0 | L18: =IF(OR(D18="",E18=""),"GREY",IF(G18="On hold","GREY",IF(G18="Done","GREEN",IF(E18<TODAY(),"RED",IF(K18>=30,"RED",IF(K18>=15,"AMBER","GREEN")))))) -> GREEN | M18: Source: Judge_Agreement document on file. Each judge's terms are set by the organizer (John to supply).
A19: PHASE 3 - RUN AND PREPARE: tasks that start Jul 1 - Sep 30, 2027 (all finish by Sep 30; hard limit Oct 14)
A20: 12 | B20: Record roster and photos for every entry (mandatory on the online form) | C20: Project Manager | D20: =EventDate-133 -> 46569 | E20: =EventDate-104 -> 46598 | F20: =E20+14 -> 46612 | G20: Not started | H20: 0 | I20: =IF(E20="","",IF(G20="Done","Done",E20-TODAY())) -> 277 | J20: =IF(OR(D20="",E20=""),"",IF(E20>D20,MAX(0,MIN(1,(TODAY()-D20)/(E20-D20))),IF(TODAY()>=E20,1,0))) -> 0 | K20: =IF(J20="","",ROUND(J20*100-H20*100,0)) -> 0 | L20: =IF(OR(D20="",E20=""),"GREY",IF(G20="On hold","GREY",IF(G20="Done","GREEN",IF(E20<TODAY(),"RED",IF(K20>=30,"RED",IF(K20>=15,"AMBER","GREEN")))))) -> GREEN | M20: Source: Jury System plan section 16.6 and the Online Registration Standard draft.
